5:return {{["x"] = 0, ["meta"] = {["fields"] = {}, ["inventory"] = {}}, ["y"] = 0, ["z"] = 0, ["name"] = "artdeco:italianmarble"}, {["x"] = 1, ["meta"] = {["fields"] = {}, ["inventory"] = {}}, ["param2"] = 18, ["y"] = 0, ["param1"] = 92, ["z"] = 3, ["name"] = "wool:slab_black_2"}, {["x"] = 1, ["meta"] = {["fields"] = {}, ["inventory"] = {}}, ["param2"] = 18, ["y"] = 0, ["param1"] = 124, ["z"] = 5, ["name"] = "wool:slab_black_2"}, {["x"] = 1, ["meta"] = {["fields"] = {}, ["inventory"] = {}}, ["param2"] = 18, ["y"] = 0, ["param1"] = 92, ["z"] = 7, ["name"] = "wool:slab_black_2"}, {["x"] = 1, ["meta"] = {["fields"] = {}, ["inventory"] = {}}, ["param2"] = 18, ["y"] = 1, ["param1"] = 109, ["z"] = 3, ["name"] = "wool:slab_black_2"}, {["x"] = 1, ["meta"] = {["fields"] = {}, ["inventory"] = {}}, ["param2"] = 18, ["y"] = 1, ["param1"] = 141, ["z"] = 5, ["name"] = "wool:slab_black_2"}, {["x"] = 1, ["meta"] = {["fields"] = {}, ["inventory"] = {}}, ["param2"] = 18, ["y"] = 1, ["param1"] = 109, ["z"] = 7, ["name"] = "wool:slab_black_2"}, {["x"] = 2, ["meta"] = {["fields"] = {["formspec"] = "size[6,4]textarea[0,-0.3;6.5,3;text;;${text}]button_exit[2,3.4;2,1;ok;Write]background[-0.5,-0.5;7,5;bg_signs_lib.jpg]"}, ["inventory"] = {}}, ["param2"] = 4, ["y"] = 0, ["param1"] = 91, ["z"] = 2, ["name"] = "default:sign_wall_steel"}, {["x"] = 2, ["meta"] = {["fields"] = {}, ["inventory"] = {}}, ["y"] = 0, ["param1"] = 107, ["z"] = 3, ["name"] = "wool:slab_black"}, {["x"] = 2, ["meta"] = {["fields"] = {["formspec"] = "size[6,4]textarea[0,-0.3;6.5,3;text;;${text}]button_exit[2,3.4;2,1;ok;Write]background[-0.5,-0.5;7,5;bg_signs_lib.jpg]"}, ["inventory"] = {}}, ["param2"] = 4, ["y"] = 0, ["param1"] = 123, ["z"] = 4, ["name"] = "default:sign_wall_steel"}, {["x"] = 2, ["meta"] = {["fields"] = {}, ["inventory"] = {}}, ["y"] = 0, ["param1"] = 139, ["z"] = 5, ["name"] = "wool:slab_black"}, {["x"] = 2, ["meta"] = {["fields"] = {["formspec"] = "size[6,4]textarea[0,-0.3;6.5,3;text;;${text}]button_exit[2,3.4;2,1;ok;Write]background[-0.5,-0.5;7,5;bg_signs_lib.jpg]"}, ["inventory"] = {}}, ["param2"] = 4, ["y"] = 0, ["param1"] = 123, ["z"] = 6, ["name"] = "default:sign_wall_steel"}, {["x"] = 2, ["meta"] = {["fields"] = {}, ["inventory"] = {}}, ["y"] = 0, ["param1"] = 107, ["z"] = 7, ["name"] = "wool:slab_black"}, {["x"] = 2, ["meta"] = {["fields"] = {["formspec"] = "size[6,4]textarea[0,-0.3;6.5,3;text;;${text}]button_exit[2,3.4;2,1;ok;Write]background[-0.5,-0.5;7,5;bg_signs_lib.jpg]"}, ["inventory"] = {}}, ["param2"] = 5, ["y"] = 0, ["param1"] = 91, ["z"] = 8, ["name"] = "default:sign_wall_steel"}, {["x"] = 3, ["meta"] = {["fields"] = {["formspec"] = "size[6,4]textarea[0,-0.3;6.5,3;text;;${text}]button_exit[2,3.4;2,1;ok;Write]background[-0.5,-0.5;7,5;bg_signs_lib.jpg]"}, ["inventory"] = {}}, ["param2"] = 2, ["y"] = 0, ["param1"] = 91, ["z"] = 1, ["name"] = "default:sign_wall_steel"}, {["x"] = 3, ["meta"] = {["fields"] = {["formspec"] = "size[6,4]textarea[0,-0.3;6.5,3;text;;${text}]button_exit[2,3.4;2,1;ok;Write]background[-0.5,-0.5;7,5;bg_signs_lib.jpg]"}, ["inventory"] = {}}, ["param2"] = 2, ["y"] = 0, ["param1"] = 92, ["z"] = 9, ["name"] = "default:sign_wall_steel"}, {["x"] = 3, ["meta"] = {["fields"] = {}, ["inventory"] = {}}, ["param2"] = 3, ["y"] = 1, ["param1"] = 123, ["z"] = 2, ["name"] = "homedecor:glass_table_large"}, {["x"] = 3, ["meta"] = {["fields"] = {}, ["inventory"] = {}}, ["param2"] = 2, ["y"] = 1, ["param1"] = 139, ["z"] = 3, ["name"] = "homedecor:glass_table_large"}, {["x"] = 3, ["meta"] = {["fields"] = {}, ["inventory"] = {}}, ["param2"] = 2, ["y"] = 1, ["param1"] = 155, ["z"] = 4, ["name"] = "homedecor:glass_table_large"}, {["x"] = 3, ["meta"] = {["fields"] = {}, ["inventory"] = {}}, ["param2"] = 3, ["y"] = 1, ["param1"] = 171, ["z"] = 5, ["name"] = "homedecor:glass_table_large"}, {["x"] = 3, ["meta"] = {["fields"] = {}, ["inventory"] = {}}, ["y"] = 1, ["param1"] = 155, ["z"] = 6, ["name"] = "homedecor:glass_table_large"}, {["x"] = 3, ["meta"] = {["fields"] = {}, ["inventory"] = {}}, ["y"] = 1, ["param1"] = 139, ["z"] = 7, ["name"] = "homedecor:glass_table_large"}, {["x"] = 3, ["meta"] = {["fields"] = {}, ["inventory"] = {}}, ["param2"] = 3, ["y"] = 1, ["param1"] = 124, ["z"] = 8, ["name"] = "homedecor:glass_table_large"}, {["x"] = 3, ["meta"] = {["fields"] = {}, ["inventory"] = {}}, ["y"] = 3, ["param1"] = 204, ["z"] = 5, ["name"] = "homedecor:fence_wrought_iron"}, {["x"] = 3, ["meta"] = {["fields"] = {}, ["inventory"] = {}}, ["param2"] = 1, ["y"] = 4, ["param1"] = 221, ["z"] = 5, ["name"] = "homedecor:glowlight_small_cube"}, {["x"] = 4, ["meta"] = {["fields"] = {}, ["inventory"] = {}}, ["param2"] = 9, ["y"] = 0, ["param1"] = 92, ["z"] = 0, ["name"] = "wool:slab_black_2"}, {["x"] = 4, ["meta"] = {["fields"] = {}, ["inventory"] = {}}, ["param2"] = 2, ["y"] = 0, ["param1"] = 108, ["z"] = 1, ["name"] = "wool:slab_black"}, {["x"] = 4, ["meta"] = {["fields"] = {}, ["inventory"] = {}}, ["y"] = 0, ["z"] = 4, ["name"] = "moretrees:willow_planks"}, {["x"] = 4, ["meta"] = {["fields"] = {}, ["inventory"] = {}}, ["y"] = 0, ["z"] = 5, ["name"] = "moretrees:willow_planks"}, {["x"] = 4, ["meta"] = {["fields"] = {}, ["inventory"] = {}}, ["y"] = 0, ["z"] = 6, ["name"] = "moretrees:willow_planks"}, {["x"] = 4, ["meta"] = {["fields"] = {}, ["inventory"] = {}}, ["param2"] = 2, ["y"] = 0, ["param1"] = 108, ["z"] = 9, ["name"] = "wool:slab_black"}, {["x"] = 4, ["meta"] = {["fields"] = {}, ["inventory"] = {}}, ["param2"] = 7, ["y"] = 0, ["param1"] = 93, ["z"] = 10, ["name"] = "wool:slab_black_2"}, {["x"] = 4, ["meta"] = {["fields"] = {}, ["inventory"] = {}}, ["param2"] = 9, ["y"] = 1, ["param1"] = 108, ["z"] = 0, ["name"] = "wool:slab_black_2"}, {["x"] = 4, ["meta"] = {["fields"] = {}, ["inventory"] = {}}, ["param2"] = 2, ["y"] = 1, ["param1"] = 140, ["z"] = 2, ["name"] = "homedecor:glass_table_large"}, {["x"] = 4, ["meta"] = {["fields"] = {}, ["inventory"] = {}}, ["param2"] = 2, ["y"] = 1, ["param1"] = 156, ["z"] = 3, ["name"] = "homedecor:glass_table_large"}, {["x"] = 4, ["meta"] = {["fields"] = {}, ["inventory"] = {}}, ["y"] = 1, ["param1"] = 172, ["z"] = 4, ["name"] = "homedecor:candlestick_wrought_iron"}, {["x"] = 4, ["meta"] = {["fields"] = {}, ["inventory"] = {}}, ["y"] = 1, ["param1"] = 172, ["z"] = 6, ["name"] = "homedecor:candlestick_wrought_iron"}, {["x"] = 4, ["meta"] = {["fields"] = {}, ["inventory"] = {}}, ["y"] = 1, ["param1"] = 156, ["z"] = 7, ["name"] = "homedecor:glass_table_large"}, {["x"] = 4, ["meta"] = {["fields"] = {}, ["inventory"] = {}}, ["y"] = 1, ["param1"] = 140, ["z"] = 8, ["name"] = "homedecor:glass_table_large"}, {["x"] = 4, ["meta"] = {["fields"] = {}, ["inventory"] = {}}, ["param2"] = 7, ["y"] = 1, ["param1"] = 110, ["z"] = 10, ["name"] = "wool:slab_black_2"}, {["x"] = 4, ["meta"] = {["fields"] = {}, ["inventory"] = {}}, ["param2"] = 3, ["y"] = 3, ["param1"] = 204, ["z"] = 4, ["name"] = "homedecor:fence_wrought_iron"}, {["x"] = 4, ["meta"] = {["fields"] = {}, ["inventory"] = {}}, ["param2"] = 3, ["y"] = 3, ["param1"] = 188, ["z"] = 5, ["name"] = "homedecor:fence_wrought_iron"}, {["x"] = 4, ["meta"] = {["fields"] = {}, ["inventory"] = {}}, ["param2"] = 2, ["y"] = 3, ["param1"] = 204, ["z"] = 6, ["name"] = "homedecor:fence_wrought_iron"}, {["x"] = 4, ["meta"] = {["fields"] = {}, ["inventory"] = {}}, ["param2"] = 1, ["y"] = 4, ["param1"] = 221, ["z"] = 4, ["name"] = "homedecor:glowlight_small_cube"}, {["x"] = 4, ["meta"] = {["fields"] = {}, ["inventory"] = {}}, ["y"] = 4, ["param1"] = 204, ["z"] = 5, ["name"] = "chains:chain_top"}, {["x"] = 4, ["meta"] = {["fields"] = {}, ["inventory"] = {}}, ["param2"] = 1, ["y"] = 4, ["param1"] = 221, ["z"] = 6, ["name"] = "homedecor:glowlight_small_cube"}, {["x"] = 5, ["meta"] = {["fields"] = {["formspec"] = "size[6,4]textarea[0,-0.3;6.5,3;text;;${text}]button_exit[2,3.4;2,1;ok;Write]background[-0.5,-0.5;7,5;bg_signs_lib.jpg]"}, ["inventory"] = {}}, ["param2"] = 3, ["y"] = 0, ["param1"] = 93, ["z"] = 1, ["name"] = "default:sign_wall_steel"}, {["x"] = 5, ["meta"] = {["fields"] = {["formspec"] = "size[6,4]textarea[0,-0.3;6.5,3;text;;${text}]button_exit[2,3.4;2,1;ok;Write]background[-0.5,-0.5;7,5;bg_signs_lib.jpg]"}, ["inventory"] = {}}, ["param2"] = 3, ["y"] = 0, ["param1"] = 93, ["z"] = 9, ["name"] = "default:sign_wall_steel"}, {["x"] = 5, ["meta"] = {["fields"] = {}, ["inventory"] = {}}, ["param2"] = 2, ["y"] = 1, ["param1"] = 125, ["z"] = 2, ["name"] = "homedecor:glass_table_large"}, {["x"] = 5, ["meta"] = {["fields"] = {}, ["inventory"] = {}}, ["param2"] = 2, ["y"] = 1, ["param1"] = 141, ["z"] = 3, ["name"] = "homedecor:glass_table_large"}, {["x"] = 5, ["meta"] = {["fields"] = {}, ["inventory"] = {}}, ["param2"] = 2, ["y"] = 1, ["param1"] = 157, ["z"] = 4, ["name"] = "homedecor:glass_table_large"}, {["x"] = 5, ["meta"] = {["fields"] = {}, ["inventory"] = {}}, ["param2"] = 1, ["y"] = 1, ["param1"] = 173, ["z"] = 5, ["name"] = "homedecor:glass_table_large"}, {["x"] = 5, ["meta"] = {["fields"] = {}, ["inventory"] = {}}, ["param2"] = 1, ["y"] = 1, ["param1"] = 157, ["z"] = 6, ["name"] = "homedecor:glass_table_large"}, {["x"] = 5, ["meta"] = {["fields"] = {}, ["inventory"] = {}}, ["y"] = 1, ["param1"] = 141, ["z"] = 7, ["name"] = "homedecor:glass_table_large"}, {["x"] = 5, ["meta"] = {["fields"] = {}, ["inventory"] = {}}, ["y"] = 1, ["param1"] = 124, ["z"] = 8, ["name"] = "homedecor:glass_table_large"}, {["x"] = 5, ["meta"] = {["fields"] = {}, ["inventory"] = {}}, ["y"] = 3, ["param1"] = 205, ["z"] = 5, ["name"] = "homedecor:fence_wrought_iron"}, {["x"] = 5, ["meta"] = {["fields"] = {}, ["inventory"] = {}}, ["param2"] = 1, ["y"] = 4, ["param1"] = 221, ["z"] = 5, ["name"] = "homedecor:glowlight_small_cube"}, {["x"] = 6, ["meta"] = {["fields"] = {["formspec"] = "size[6,4]textarea[0,-0.3;6.5,3;text;;${text}]button_exit[2,3.4;2,1;ok;Write]background[-0.5,-0.5;7,5;bg_signs_lib.jpg]"}, ["inventory"] = {}}, ["param2"] = 4, ["y"] = 0, ["param1"] = 94, ["z"] = 2, ["name"] = "default:sign_wall_steel"}, {["x"] = 6, ["meta"] = {["fields"] = {}, ["inventory"] = {}}, ["param2"] = 3, ["y"] = 0, ["param1"] = 110, ["z"] = 3, ["name"] = "wool:slab_black"}, {["x"] = 6, ["meta"] = {["fields"] = {["formspec"] = "size[6,4]textarea[0,-0.3;6.5,3;text;;${text}]button_exit[2,3.4;2,1;ok;Write]background[-0.5,-0.5;7,5;bg_signs_lib.jpg]"}, ["inventory"] = {}}, ["param2"] = 4, ["y"] = 0, ["param1"] = 126, ["z"] = 4, ["name"] = "default:sign_wall_steel"}, {["x"] = 6, ["meta"] = {["fields"] = {}, ["inventory"] = {}}, ["param2"] = 3, ["y"] = 0, ["param1"] = 142, ["z"] = 5, ["name"] = "wool:slab_black"}, {["x"] = 6, ["meta"] = {["fields"] = {["formspec"] = "size[6,4]textarea[0,-0.3;6.5,3;text;;${text}]button_exit[2,3.4;2,1;ok;Write]background[-0.5,-0.5;7,5;bg_signs_lib.jpg]"}, ["inventory"] = {}}, ["param2"] = 4, ["y"] = 0, ["param1"] = 126, ["z"] = 6, ["name"] = "default:sign_wall_steel"}, {["x"] = 6, ["meta"] = {["fields"] = {}, ["inventory"] = {}}, ["param2"] = 3, ["y"] = 0, ["param1"] = 110, ["z"] = 7, ["name"] = "wool:slab_black"}, {["x"] = 6, ["meta"] = {["fields"] = {["formspec"] = "size[6,4]textarea[0,-0.3;6.5,3;text;;${text}]button_exit[2,3.4;2,1;ok;Write]background[-0.5,-0.5;7,5;bg_signs_lib.jpg]"}, ["inventory"] = {}}, ["param2"] = 5, ["y"] = 0, ["param1"] = 93, ["z"] = 8, ["name"] = "default:sign_wall_steel"}, {["x"] = 7, ["meta"] = {["fields"] = {}, ["inventory"] = {}}, ["param2"] = 12, ["y"] = 0, ["param1"] = 95, ["z"] = 3, ["name"] = "wool:slab_black_2"}, {["x"] = 7, ["meta"] = {["fields"] = {}, ["inventory"] = {}}, ["param2"] = 12, ["y"] = 0, ["param1"] = 127, ["z"] = 5, ["name"] = "wool:slab_black_2"}, {["x"] = 7, ["meta"] = {["fields"] = {}, ["inventory"] = {}}, ["param2"] = 12, ["y"] = 0, ["param1"] = 95, ["z"] = 7, ["name"] = "wool:slab_black_2"}, {["x"] = 7, ["meta"] = {["fields"] = {}, ["inventory"] = {}}, ["y"] = 0, ["z"] = 10, ["name"] = "artdeco:italianmarble"}, {["x"] = 7, ["meta"] = {["fields"] = {}, ["inventory"] = {}}, ["param2"] = 12, ["y"] = 1, ["param1"] = 111, ["z"] = 3, ["name"] = "wool:slab_black_2"}, {["x"] = 7, ["meta"] = {["fields"] = {}, ["inventory"] = {}}, ["param2"] = 12, ["y"] = 1, ["param1"] = 143, ["z"] = 5, ["name"] = "wool:slab_black_2"}, {["x"] = 7, ["meta"] = {["fields"] = {}, ["inventory"] = {}}, ["param2"] = 12, ["y"] = 1, ["param1"] = 111, ["z"] = 7, ["name"] = "wool:slab_black_2"}, {["x"] = 7, ["meta"] = {["fields"] = {}, ["inventory"] = {}}, ["y"] = 1, ["z"] = 10, ["name"] = "artdeco:italianmarble"}, {["x"] = 7, ["meta"] = {["fields"] = {}, ["inventory"] = {}}, ["y"] = 2, ["z"] = 10, ["name"] = "artdeco:italianmarble"}, {["x"] = 7, ["meta"] = {["fields"] = {}, ["inventory"] = {}}, ["y"] = 3, ["z"] = 10, ["name"] = "artdeco:italianmarble"}, {["x"] = 7, ["meta"] = {["fields"] = {}, ["inventory"] = {}}, ["y"] = 4, ["z"] = 10, ["name"] = "artdeco:italianmarble"}}