5:return {{["x"] = 0, ["meta"] = {["fields"] = {}, ["inventory"] = {}}, ["y"] = 0, ["z"] = 0, ["name"] = "colored_clay:hardened"}, {["x"] = 0, ["meta"] = {["fields"] = {}, ["inventory"] = {}}, ["param2"] = 16, ["y"] = 0, ["param1"] = 47, ["z"] = 3, ["name"] = "mydeck:deck_boards"}, {["x"] = 0, ["meta"] = {["fields"] = {}, ["inventory"] = {}}, ["param2"] = 17, ["y"] = 2, ["param1"] = 47, ["z"] = 1, ["name"] = "wool:panel_white_1"}, {["x"] = 0, ["meta"] = {["fields"] = {}, ["inventory"] = {}}, ["param2"] = 17, ["y"] = 2, ["param1"] = 63, ["z"] = 2, ["name"] = "wool:panel_white_1"}, {["x"] = 0, ["meta"] = {["fields"] = {}, ["inventory"] = {}}, ["param2"] = 17, ["y"] = 2, ["param1"] = 79, ["z"] = 3, ["name"] = "wool:panel_white_1"}, {["x"] = 0, ["meta"] = {["fields"] = {}, ["inventory"] = {}}, ["param2"] = 17, ["y"] = 2, ["param1"] = 95, ["z"] = 4, ["name"] = "wool:panel_white_1"}, {["x"] = 0, ["meta"] = {["fields"] = {}, ["inventory"] = {}}, ["param2"] = 17, ["y"] = 2, ["param1"] = 111, ["z"] = 5, ["name"] = "wool:panel_white_1"}, {["x"] = 1, ["meta"] = {["fields"] = {}, ["inventory"] = {}}, ["param2"] = 1, ["y"] = 0, ["param1"] = 63, ["z"] = 3, ["name"] = "wool:slab_dark_grey"}, {["x"] = 1, ["meta"] = {["fields"] = {}, ["inventory"] = {}}, ["y"] = 0, ["param1"] = 79, ["z"] = 4, ["name"] = "flowers:tulip"}, {["x"] = 1, ["meta"] = {["fields"] = {}, ["inventory"] = {}}, ["param2"] = 8, ["y"] = 2, ["param1"] = 47, ["z"] = 0, ["name"] = "wool:panel_white_1"}, {["x"] = 1, ["meta"] = {["fields"] = {}, ["inventory"] = {}}, ["param2"] = 6, ["y"] = 2, ["param1"] = 143, ["z"] = 6, ["name"] = "wool:panel_white_1"}, {["x"] = 1, ["meta"] = {["fields"] = {}, ["inventory"] = {}}, ["y"] = 3, ["param1"] = 47, ["z"] = 1, ["name"] = "wool:slab_white_1"}, {["x"] = 1, ["meta"] = {["fields"] = {}, ["inventory"] = {}}, ["param2"] = 1, ["y"] = 3, ["param1"] = 63, ["z"] = 2, ["name"] = "wool:slab_white_1"}, {["x"] = 1, ["meta"] = {["fields"] = {}, ["inventory"] = {}}, ["param2"] = 1, ["y"] = 3, ["param1"] = 79, ["z"] = 3, ["name"] = "wool:slab_white_1"}, {["x"] = 1, ["meta"] = {["fields"] = {}, ["inventory"] = {}}, ["y"] = 3, ["param1"] = 95, ["z"] = 4, ["name"] = "wool:slab_white_1"}, {["x"] = 1, ["meta"] = {["fields"] = {}, ["inventory"] = {}}, ["param2"] = 1, ["y"] = 3, ["param1"] = 111, ["z"] = 5, ["name"] = "wool:slab_white_1"}, {["x"] = 2, ["meta"] = {["fields"] = {}, ["inventory"] = {}}, ["param2"] = 2, ["y"] = 1, ["param1"] = 79, ["z"] = 2, ["name"] = "mydeck:deck_boards"}, {["x"] = 2, ["meta"] = {["fields"] = {}, ["inventory"] = {}}, ["param2"] = 2, ["y"] = 1, ["param1"] = 95, ["z"] = 3, ["name"] = "mydeck:deck_boards"}, {["x"] = 2, ["meta"] = {["fields"] = {}, ["inventory"] = {}}, ["param2"] = 2, ["y"] = 1, ["param1"] = 111, ["z"] = 4, ["name"] = "mydeck:deck_boards"}, {["x"] = 2, ["meta"] = {["fields"] = {}, ["inventory"] = {}}, ["param2"] = 8, ["y"] = 2, ["param1"] = 63, ["z"] = 0, ["name"] = "wool:panel_white_1"}, {["x"] = 2, ["meta"] = {["fields"] = {}, ["inventory"] = {}}, ["param2"] = 6, ["y"] = 2, ["param1"] = 159, ["z"] = 6, ["name"] = "wool:panel_white_1"}, {["x"] = 2, ["meta"] = {["fields"] = {}, ["inventory"] = {}}, ["y"] = 3, ["param1"] = 63, ["z"] = 1, ["name"] = "wool:slab_white_1"}, {["x"] = 2, ["meta"] = {["fields"] = {}, ["inventory"] = {}}, ["param2"] = 1, ["y"] = 3, ["param1"] = 79, ["z"] = 2, ["name"] = "wool:slab_white_2"}, {["x"] = 2, ["meta"] = {["fields"] = {}, ["inventory"] = {}}, ["param2"] = 2, ["y"] = 3, ["param1"] = 95, ["z"] = 3, ["name"] = "wool:slab_white_2"}, {["x"] = 2, ["meta"] = {["fields"] = {}, ["inventory"] = {}}, ["param2"] = 3, ["y"] = 3, ["param1"] = 111, ["z"] = 4, ["name"] = "wool:slab_white_2"}, {["x"] = 2, ["meta"] = {["fields"] = {}, ["inventory"] = {}}, ["param2"] = 1, ["y"] = 3, ["param1"] = 127, ["z"] = 5, ["name"] = "wool:slab_white_1"}, {["x"] = 3, ["meta"] = {["fields"] = {}, ["inventory"] = {}}, ["param2"] = 9, ["y"] = 0, ["param1"] = 47, ["z"] = 0, ["name"] = "mydeck:deck_boards"}, {["x"] = 3, ["meta"] = {["fields"] = {}, ["inventory"] = {}}, ["y"] = 0, ["param1"] = 63, ["z"] = 1, ["name"] = "wool:slab_dark_grey"}, {["x"] = 3, ["meta"] = {["fields"] = {}, ["inventory"] = {}}, ["y"] = 0, ["z"] = 3, ["name"] = "vehicles:concrete"}, {["x"] = 3, ["meta"] = {["fields"] = {}, ["inventory"] = {}}, ["param2"] = 2, ["y"] = 0, ["param1"] = 127, ["z"] = 5, ["name"] = "wool:slab_dark_grey"}, {["x"] = 3, ["meta"] = {["fields"] = {}, ["inventory"] = {}}, ["param2"] = 5, ["y"] = 0, ["param1"] = 143, ["z"] = 6, ["name"] = "mydeck:deck_boards"}, {["x"] = 3, ["meta"] = {["fields"] = {}, ["inventory"] = {}}, ["param2"] = 2, ["y"] = 1, ["param1"] = 95, ["z"] = 2, ["name"] = "mydeck:deck_boards"}, {["x"] = 3, ["meta"] = {["fields"] = {}, ["inventory"] = {}}, ["y"] = 1, ["param1"] = 110, ["z"] = 3, ["name"] = "homedecor:pole_wrought_iron"}, {["x"] = 3, ["meta"] = {["fields"] = {}, ["inventory"] = {}}, ["param2"] = 2, ["y"] = 1, ["param1"] = 127, ["z"] = 4, ["name"] = "mydeck:deck_boards"}, {["x"] = 3, ["meta"] = {["fields"] = {}, ["inventory"] = {}}, ["param2"] = 8, ["y"] = 2, ["param1"] = 79, ["z"] = 0, ["name"] = "wool:panel_white_1"}, {["x"] = 3, ["meta"] = {["fields"] = {}, ["inventory"] = {}}, ["y"] = 2, ["param1"] = 126, ["z"] = 3, ["name"] = "homedecor:pole_wrought_iron"}, {["x"] = 3, ["meta"] = {["fields"] = {}, ["inventory"] = {}}, ["param2"] = 6, ["y"] = 2, ["param1"] = 175, ["z"] = 6, ["name"] = "wool:panel_white_1"}, {["x"] = 3, ["meta"] = {["fields"] = {}, ["inventory"] = {}}, ["y"] = 3, ["param1"] = 79, ["z"] = 1, ["name"] = "wool:slab_white_1"}, {["x"] = 3, ["meta"] = {["fields"] = {}, ["inventory"] = {}}, ["param2"] = 1, ["y"] = 3, ["param1"] = 95, ["z"] = 2, ["name"] = "wool:slab_white_2"}, {["x"] = 3, ["meta"] = {["fields"] = {}, ["inventory"] = {}}, ["param2"] = 1, ["y"] = 3, ["param1"] = 111, ["z"] = 3, ["name"] = "wool:slab_white_quarter"}, {["x"] = 3, ["meta"] = {["fields"] = {}, ["inventory"] = {}}, ["param2"] = 3, ["y"] = 3, ["param1"] = 127, ["z"] = 4, ["name"] = "wool:slab_white_2"}, {["x"] = 3, ["meta"] = {["fields"] = {}, ["inventory"] = {}}, ["param2"] = 2, ["y"] = 3, ["param1"] = 143, ["z"] = 5, ["name"] = "wool:slab_white_1"}, {["x"] = 4, ["meta"] = {["fields"] = {}, ["inventory"] = {}}, ["param2"] = 2, ["y"] = 1, ["param1"] = 111, ["z"] = 2, ["name"] = "mydeck:deck_boards"}, {["x"] = 4, ["meta"] = {["fields"] = {}, ["inventory"] = {}}, ["param2"] = 2, ["y"] = 1, ["param1"] = 127, ["z"] = 3, ["name"] = "mydeck:deck_boards"}, {["x"] = 4, ["meta"] = {["fields"] = {}, ["inventory"] = {}}, ["param2"] = 2, ["y"] = 1, ["param1"] = 143, ["z"] = 4, ["name"] = "mydeck:deck_boards"}, {["x"] = 4, ["meta"] = {["fields"] = {}, ["inventory"] = {}}, ["param2"] = 8, ["y"] = 2, ["param1"] = 95, ["z"] = 0, ["name"] = "wool:panel_white_1"}, {["x"] = 4, ["meta"] = {["fields"] = {}, ["inventory"] = {}}, ["param2"] = 6, ["y"] = 2, ["param1"] = 191, ["z"] = 6, ["name"] = "wool:panel_white_1"}, {["x"] = 4, ["meta"] = {["fields"] = {}, ["inventory"] = {}}, ["param2"] = 3, ["y"] = 3, ["param1"] = 95, ["z"] = 1, ["name"] = "wool:slab_white_1"}, {["x"] = 4, ["meta"] = {["fields"] = {}, ["inventory"] = {}}, ["param2"] = 1, ["y"] = 3, ["param1"] = 111, ["z"] = 2, ["name"] = "wool:slab_white_2"}, {["x"] = 4, ["meta"] = {["fields"] = {}, ["inventory"] = {}}, ["y"] = 3, ["param1"] = 127, ["z"] = 3, ["name"] = "wool:slab_white_2"}, {["x"] = 4, ["meta"] = {["fields"] = {}, ["inventory"] = {}}, ["param2"] = 3, ["y"] = 3, ["param1"] = 143, ["z"] = 4, ["name"] = "wool:slab_white_2"}, {["x"] = 4, ["meta"] = {["fields"] = {}, ["inventory"] = {}}, ["param2"] = 1, ["y"] = 3, ["param1"] = 159, ["z"] = 5, ["name"] = "wool:slab_white_1"}, {["x"] = 5, ["meta"] = {["fields"] = {}, ["inventory"] = {}}, ["y"] = 0, ["param1"] = 127, ["z"] = 3, ["name"] = "wool:slab_dark_grey"}, {["x"] = 5, ["meta"] = {["fields"] = {}, ["inventory"] = {}}, ["param2"] = 8, ["y"] = 2, ["param1"] = 111, ["z"] = 0, ["name"] = "wool:panel_white_1"}, {["x"] = 5, ["meta"] = {["fields"] = {}, ["inventory"] = {}}, ["param2"] = 6, ["y"] = 2, ["param1"] = 207, ["z"] = 6, ["name"] = "wool:panel_white_1"}, {["x"] = 5, ["meta"] = {["fields"] = {}, ["inventory"] = {}}, ["param2"] = 3, ["y"] = 3, ["param1"] = 111, ["z"] = 1, ["name"] = "wool:slab_white_1"}, {["x"] = 5, ["meta"] = {["fields"] = {}, ["inventory"] = {}}, ["param2"] = 3, ["y"] = 3, ["param1"] = 127, ["z"] = 2, ["name"] = "wool:slab_white_1"}, {["x"] = 5, ["meta"] = {["fields"] = {}, ["inventory"] = {}}, ["param2"] = 3, ["y"] = 3, ["param1"] = 143, ["z"] = 3, ["name"] = "wool:slab_white_1"}, {["x"] = 5, ["meta"] = {["fields"] = {}, ["inventory"] = {}}, ["param2"] = 2, ["y"] = 3, ["param1"] = 159, ["z"] = 4, ["name"] = "wool:slab_white_1"}, {["x"] = 5, ["meta"] = {["fields"] = {}, ["inventory"] = {}}, ["param2"] = 2, ["y"] = 3, ["param1"] = 175, ["z"] = 5, ["name"] = "wool:slab_white_1"}, {["x"] = 6, ["meta"] = {["fields"] = {}, ["inventory"] = {}}, ["y"] = 0, ["param1"] = 127, ["z"] = 2, ["name"] = "flowers:dandelion_yellow"}, {["x"] = 6, ["meta"] = {["fields"] = {}, ["inventory"] = {}}, ["param2"] = 12, ["y"] = 0, ["param1"] = 143, ["z"] = 3, ["name"] = "mydeck:deck_boards"}, {["x"] = 6, ["meta"] = {["fields"] = {}, ["inventory"] = {}}, ["param2"] = 3, ["y"] = 0, ["param1"] = 190, ["z"] = 6, ["name"] = "homedecor:pole_wrought_iron"}, {["x"] = 6, ["meta"] = {["fields"] = {}, ["inventory"] = {}}, ["param2"] = 3, ["y"] = 1, ["param1"] = 206, ["z"] = 6, ["name"] = "homedecor:pole_wrought_iron"}, {["x"] = 6, ["meta"] = {["fields"] = {}, ["inventory"] = {}}, ["param2"] = 15, ["y"] = 2, ["param1"] = 143, ["z"] = 1, ["name"] = "wool:panel_white_1"}, {["x"] = 6, ["meta"] = {["fields"] = {}, ["inventory"] = {}}, ["param2"] = 15, ["y"] = 2, ["param1"] = 159, ["z"] = 2, ["name"] = "wool:panel_white_1"}, {["x"] = 6, ["meta"] = {["fields"] = {}, ["inventory"] = {}}, ["param2"] = 15, ["y"] = 2, ["param1"] = 175, ["z"] = 3, ["name"] = "wool:panel_white_1"}, {["x"] = 6, ["meta"] = {["fields"] = {}, ["inventory"] = {}}, ["param2"] = 15, ["y"] = 2, ["param1"] = 191, ["z"] = 4, ["name"] = "wool:panel_white_1"}, {["x"] = 6, ["meta"] = {["fields"] = {}, ["inventory"] = {}}, ["param2"] = 15, ["y"] = 2, ["param1"] = 207, ["z"] = 5, ["name"] = "wool:panel_white_1"}, {["x"] = 6, ["meta"] = {["fields"] = {}, ["inventory"] = {}}, ["param2"] = 1, ["y"] = 2, ["param1"] = 222, ["z"] = 6, ["name"] = "homedecor:glowlight_small_cube"}, {["x"] = 7, ["meta"] = {["fields"] = {}, ["inventory"] = {}}, ["y"] = 0, ["param1"] = 127, ["z"] = 3, ["name"] = "flowers:tulip"}}