5:return {{["x"] = 0, ["meta"] = {["fields"] = {}, ["inventory"] = {}}, ["param2"] = 18, ["y"] = 0, ["param1"] = 63, ["z"] = 3, ["name"] = "moreblocks:slab_sandstone_block_1"}, {["x"] = 0, ["meta"] = {["fields"] = {}, ["inventory"] = {}}, ["param2"] = 17, ["y"] = 2, ["param1"] = 63, ["z"] = 1, ["name"] = "wool:panel_white_1"}, {["x"] = 0, ["meta"] = {["fields"] = {}, ["inventory"] = {}}, ["param2"] = 17, ["y"] = 2, ["param1"] = 79, ["z"] = 2, ["name"] = "wool:panel_white_1"}, {["x"] = 0, ["meta"] = {["fields"] = {}, ["inventory"] = {}}, ["param2"] = 17, ["y"] = 2, ["param1"] = 95, ["z"] = 3, ["name"] = "wool:panel_white_1"}, {["x"] = 0, ["meta"] = {["fields"] = {}, ["inventory"] = {}}, ["param2"] = 17, ["y"] = 2, ["param1"] = 110, ["z"] = 4, ["name"] = "wool:panel_white_1"}, {["x"] = 0, ["meta"] = {["fields"] = {}, ["inventory"] = {}}, ["param2"] = 17, ["y"] = 2, ["param1"] = 126, ["z"] = 5, ["name"] = "wool:panel_white_1"}, {["x"] = 1, ["meta"] = {["fields"] = {}, ["inventory"] = {}}, ["param2"] = 10, ["y"] = 0, ["param1"] = 95, ["z"] = 2, ["name"] = "moreblocks:panel_sandstone_block_1"}, {["x"] = 1, ["meta"] = {["fields"] = {}, ["inventory"] = {}}, ["param2"] = 1, ["y"] = 0, ["param1"] = 79, ["z"] = 3, ["name"] = "wool:slab_dark_grey"}, {["x"] = 1, ["meta"] = {["fields"] = {}, ["inventory"] = {}}, ["param2"] = 4, ["y"] = 0, ["param1"] = 62, ["z"] = 4, ["name"] = "moreblocks:panel_sandstone_block_1"}, {["x"] = 1, ["meta"] = {["fields"] = {}, ["inventory"] = {}}, ["param2"] = 8, ["y"] = 2, ["param1"] = 95, ["z"] = 0, ["name"] = "wool:panel_white_1"}, {["x"] = 1, ["meta"] = {["fields"] = {}, ["inventory"] = {}}, ["param2"] = 6, ["y"] = 2, ["param1"] = 127, ["z"] = 6, ["name"] = "wool:panel_white_1"}, {["x"] = 1, ["meta"] = {["fields"] = {}, ["inventory"] = {}}, ["y"] = 3, ["param1"] = 63, ["z"] = 1, ["name"] = "wool:slab_white_1"}, {["x"] = 1, ["meta"] = {["fields"] = {}, ["inventory"] = {}}, ["param2"] = 1, ["y"] = 3, ["param1"] = 79, ["z"] = 2, ["name"] = "wool:slab_white_1"}, {["x"] = 1, ["meta"] = {["fields"] = {}, ["inventory"] = {}}, ["param2"] = 1, ["y"] = 3, ["param1"] = 95, ["z"] = 3, ["name"] = "wool:slab_white_1"}, {["x"] = 1, ["meta"] = {["fields"] = {}, ["inventory"] = {}}, ["y"] = 3, ["param1"] = 110, ["z"] = 4, ["name"] = "wool:slab_white_1"}, {["x"] = 1, ["meta"] = {["fields"] = {}, ["inventory"] = {}}, ["param2"] = 1, ["y"] = 3, ["param1"] = 126, ["z"] = 5, ["name"] = "wool:slab_white_1"}, {["x"] = 2, ["meta"] = {["fields"] = {}, ["inventory"] = {}}, ["param2"] = 19, ["y"] = 0, ["param1"] = 127, ["z"] = 1, ["name"] = "moreblocks:panel_sandstone_block_1"}, {["x"] = 2, ["meta"] = {["fields"] = {}, ["inventory"] = {}}, ["param2"] = 20, ["y"] = 0, ["param1"] = 111, ["z"] = 2, ["name"] = "moreblocks:slab_sandstone_block_1"}, {["x"] = 2, ["meta"] = {["fields"] = {}, ["inventory"] = {}}, ["param2"] = 20, ["y"] = 0, ["param1"] = 95, ["z"] = 3, ["name"] = "moreblocks:slab_sandstone_block_1"}, {["x"] = 2, ["meta"] = {["fields"] = {}, ["inventory"] = {}}, ["param2"] = 20, ["y"] = 0, ["param1"] = 78, ["z"] = 4, ["name"] = "moreblocks:slab_sandstone_block_1"}, {["x"] = 2, ["meta"] = {["fields"] = {}, ["inventory"] = {}}, ["param2"] = 19, ["y"] = 0, ["param1"] = 62, ["z"] = 5, ["name"] = "moreblocks:panel_sandstone_block_1"}, {["x"] = 2, ["meta"] = {["fields"] = {}, ["inventory"] = {}}, ["param2"] = 8, ["y"] = 2, ["param1"] = 111, ["z"] = 0, ["name"] = "wool:panel_white_1"}, {["x"] = 2, ["meta"] = {["fields"] = {}, ["inventory"] = {}}, ["param2"] = 6, ["y"] = 2, ["param1"] = 111, ["z"] = 6, ["name"] = "wool:panel_white_1"}, {["x"] = 2, ["meta"] = {["fields"] = {}, ["inventory"] = {}}, ["y"] = 3, ["param1"] = 79, ["z"] = 1, ["name"] = "wool:slab_white_1"}, {["x"] = 2, ["meta"] = {["fields"] = {}, ["inventory"] = {}}, ["param2"] = 1, ["y"] = 3, ["param1"] = 63, ["z"] = 2, ["name"] = "wool:slab_white_2"}, {["x"] = 2, ["meta"] = {["fields"] = {}, ["inventory"] = {}}, ["param2"] = 2, ["y"] = 3, ["param1"] = 79, ["z"] = 3, ["name"] = "wool:slab_white_2"}, {["x"] = 2, ["meta"] = {["fields"] = {}, ["inventory"] = {}}, ["param2"] = 3, ["y"] = 3, ["param1"] = 94, ["z"] = 4, ["name"] = "wool:slab_white_2"}, {["x"] = 2, ["meta"] = {["fields"] = {}, ["inventory"] = {}}, ["param2"] = 1, ["y"] = 3, ["param1"] = 110, ["z"] = 5, ["name"] = "wool:slab_white_1"}, {["x"] = 3, ["meta"] = {["fields"] = {}, ["inventory"] = {}}, ["param2"] = 9, ["y"] = 0, ["param1"] = 159, ["z"] = 0, ["name"] = "moreblocks:slab_sandstone_block_1"}, {["x"] = 3, ["meta"] = {["fields"] = {}, ["inventory"] = {}}, ["y"] = 0, ["param1"] = 143, ["z"] = 1, ["name"] = "wool:slab_dark_grey"}, {["x"] = 3, ["meta"] = {["fields"] = {}, ["inventory"] = {}}, ["param2"] = 20, ["y"] = 0, ["param1"] = 127, ["z"] = 2, ["name"] = "moreblocks:slab_sandstone_block_1"}, {["x"] = 3, ["meta"] = {["fields"] = {}, ["inventory"] = {}}, ["y"] = 0, ["z"] = 3, ["name"] = "default:sandstone_block"}, {["x"] = 3, ["meta"] = {["fields"] = {}, ["inventory"] = {}}, ["param2"] = 20, ["y"] = 0, ["param1"] = 61, ["z"] = 4, ["name"] = "moreblocks:slab_sandstone_block_1"}, {["x"] = 3, ["meta"] = {["fields"] = {}, ["inventory"] = {}}, ["param2"] = 2, ["y"] = 0, ["param1"] = 46, ["z"] = 5, ["name"] = "wool:slab_dark_grey"}, {["x"] = 3, ["meta"] = {["fields"] = {}, ["inventory"] = {}}, ["param2"] = 7, ["y"] = 0, ["param1"] = 63, ["z"] = 6, ["name"] = "moreblocks:slab_sandstone_block_1"}, {["x"] = 3, ["meta"] = {["fields"] = {}, ["inventory"] = {}}, ["y"] = 1, ["param1"] = 94, ["z"] = 3, ["name"] = "homedecor:pole_wrought_iron"}, {["x"] = 3, ["meta"] = {["fields"] = {}, ["inventory"] = {}}, ["param2"] = 8, ["y"] = 2, ["param1"] = 127, ["z"] = 0, ["name"] = "wool:panel_white_1"}, {["x"] = 3, ["meta"] = {["fields"] = {}, ["inventory"] = {}}, ["y"] = 2, ["param1"] = 78, ["z"] = 3, ["name"] = "homedecor:pole_wrought_iron"}, {["x"] = 3, ["meta"] = {["fields"] = {}, ["inventory"] = {}}, ["param2"] = 6, ["y"] = 2, ["param1"] = 95, ["z"] = 6, ["name"] = "wool:panel_white_1"}, {["x"] = 3, ["meta"] = {["fields"] = {}, ["inventory"] = {}}, ["y"] = 3, ["param1"] = 95, ["z"] = 1, ["name"] = "wool:slab_white_1"}, {["x"] = 3, ["meta"] = {["fields"] = {}, ["inventory"] = {}}, ["param2"] = 1, ["y"] = 3, ["param1"] = 79, ["z"] = 2, ["name"] = "wool:slab_white_2"}, {["x"] = 3, ["meta"] = {["fields"] = {}, ["inventory"] = {}}, ["param2"] = 1, ["y"] = 3, ["param1"] = 63, ["z"] = 3, ["name"] = "wool:slab_white_quarter"}, {["x"] = 3, ["meta"] = {["fields"] = {}, ["inventory"] = {}}, ["param2"] = 3, ["y"] = 3, ["param1"] = 78, ["z"] = 4, ["name"] = "wool:slab_white_2"}, {["x"] = 3, ["meta"] = {["fields"] = {}, ["inventory"] = {}}, ["param2"] = 2, ["y"] = 3, ["param1"] = 94, ["z"] = 5, ["name"] = "wool:slab_white_1"}, {["x"] = 4, ["meta"] = {["fields"] = {}, ["inventory"] = {}}, ["param2"] = 13, ["y"] = 0, ["param1"] = 127, ["z"] = 1, ["name"] = "moreblocks:panel_sandstone_block_1"}, {["x"] = 4, ["meta"] = {["fields"] = {}, ["inventory"] = {}}, ["param2"] = 20, ["y"] = 0, ["param1"] = 111, ["z"] = 2, ["name"] = "moreblocks:slab_sandstone_block_1"}, {["x"] = 4, ["meta"] = {["fields"] = {}, ["inventory"] = {}}, ["param2"] = 20, ["y"] = 0, ["param1"] = 95, ["z"] = 3, ["name"] = "moreblocks:slab_sandstone_block_1"}, {["x"] = 4, ["meta"] = {["fields"] = {}, ["inventory"] = {}}, ["param2"] = 20, ["y"] = 0, ["param1"] = 78, ["z"] = 4, ["name"] = "moreblocks:slab_sandstone_block_1"}, {["x"] = 4, ["meta"] = {["fields"] = {}, ["inventory"] = {}}, ["param2"] = 13, ["y"] = 0, ["param1"] = 62, ["z"] = 5, ["name"] = "moreblocks:panel_sandstone_block_1"}, {["x"] = 4, ["meta"] = {["fields"] = {}, ["inventory"] = {}}, ["param2"] = 8, ["y"] = 2, ["param1"] = 111, ["z"] = 0, ["name"] = "wool:panel_white_1"}, {["x"] = 4, ["meta"] = {["fields"] = {}, ["inventory"] = {}}, ["param2"] = 6, ["y"] = 2, ["param1"] = 79, ["z"] = 6, ["name"] = "wool:panel_white_1"}, {["x"] = 4, ["meta"] = {["fields"] = {}, ["inventory"] = {}}, ["param2"] = 3, ["y"] = 3, ["param1"] = 79, ["z"] = 1, ["name"] = "wool:slab_white_1"}, {["x"] = 4, ["meta"] = {["fields"] = {}, ["inventory"] = {}}, ["param2"] = 1, ["y"] = 3, ["param1"] = 63, ["z"] = 2, ["name"] = "wool:slab_white_2"}, {["x"] = 4, ["meta"] = {["fields"] = {}, ["inventory"] = {}}, ["y"] = 3, ["param1"] = 47, ["z"] = 3, ["name"] = "wool:slab_white_2"}, {["x"] = 4, ["meta"] = {["fields"] = {}, ["inventory"] = {}}, ["param2"] = 3, ["y"] = 3, ["param1"] = 62, ["z"] = 4, ["name"] = "wool:slab_white_2"}, {["x"] = 4, ["meta"] = {["fields"] = {}, ["inventory"] = {}}, ["param2"] = 1, ["y"] = 3, ["param1"] = 78, ["z"] = 5, ["name"] = "wool:slab_white_1"}, {["x"] = 5, ["meta"] = {["fields"] = {}, ["inventory"] = {}}, ["param2"] = 10, ["y"] = 0, ["param1"] = 95, ["z"] = 2, ["name"] = "moreblocks:panel_sandstone_block_1"}, {["x"] = 5, ["meta"] = {["fields"] = {}, ["inventory"] = {}}, ["y"] = 0, ["param1"] = 79, ["z"] = 3, ["name"] = "wool:slab_dark_grey"}, {["x"] = 5, ["meta"] = {["fields"] = {}, ["inventory"] = {}}, ["param2"] = 4, ["y"] = 0, ["param1"] = 62, ["z"] = 4, ["name"] = "moreblocks:panel_sandstone_block_1"}, {["x"] = 5, ["meta"] = {["fields"] = {}, ["inventory"] = {}}, ["param2"] = 8, ["y"] = 2, ["param1"] = 95, ["z"] = 0, ["name"] = "wool:panel_white_1"}, {["x"] = 5, ["meta"] = {["fields"] = {}, ["inventory"] = {}}, ["param2"] = 6, ["y"] = 2, ["param1"] = 63, ["z"] = 6, ["name"] = "wool:panel_white_1"}, {["x"] = 5, ["meta"] = {["fields"] = {}, ["inventory"] = {}}, ["param2"] = 3, ["y"] = 3, ["param1"] = 63, ["z"] = 1, ["name"] = "wool:slab_white_1"}, {["x"] = 5, ["meta"] = {["fields"] = {}, ["inventory"] = {}}, ["param2"] = 3, ["y"] = 3, ["param1"] = 47, ["z"] = 2, ["name"] = "wool:slab_white_1"}, {["x"] = 5, ["meta"] = {["fields"] = {}, ["inventory"] = {}}, ["param2"] = 3, ["y"] = 3, ["param1"] = 31, ["z"] = 3, ["name"] = "wool:slab_white_1"}, {["x"] = 5, ["meta"] = {["fields"] = {}, ["inventory"] = {}}, ["param2"] = 2, ["y"] = 3, ["param1"] = 46, ["z"] = 4, ["name"] = "wool:slab_white_1"}, {["x"] = 5, ["meta"] = {["fields"] = {}, ["inventory"] = {}}, ["param2"] = 2, ["y"] = 3, ["param1"] = 62, ["z"] = 5, ["name"] = "wool:slab_white_1"}, {["x"] = 6, ["meta"] = {["fields"] = {}, ["inventory"] = {}}, ["y"] = 0, ["z"] = 0, ["name"] = "wool:grey"}, {["x"] = 6, ["meta"] = {["fields"] = {}, ["inventory"] = {}}, ["param2"] = 12, ["y"] = 0, ["param1"] = 62, ["z"] = 3, ["name"] = "moreblocks:slab_sandstone_block_1"}, {["x"] = 6, ["meta"] = {["fields"] = {}, ["inventory"] = {}}, ["param2"] = 15, ["y"] = 2, ["param1"] = 62, ["z"] = 1, ["name"] = "wool:panel_white_1"}, {["x"] = 6, ["meta"] = {["fields"] = {}, ["inventory"] = {}}, ["param2"] = 15, ["y"] = 2, ["param1"] = 46, ["z"] = 2, ["name"] = "wool:panel_white_1"}, {["x"] = 6, ["meta"] = {["fields"] = {}, ["inventory"] = {}}, ["param2"] = 15, ["y"] = 2, ["param1"] = 30, ["z"] = 3, ["name"] = "wool:panel_white_1"}, {["x"] = 6, ["meta"] = {["fields"] = {}, ["inventory"] = {}}, ["param2"] = 15, ["y"] = 2, ["param1"] = 29, ["z"] = 4, ["name"] = "wool:panel_white_1"}, {["x"] = 6, ["meta"] = {["fields"] = {}, ["inventory"] = {}}, ["param2"] = 15, ["y"] = 2, ["param1"] = 46, ["z"] = 5, ["name"] = "wool:panel_white_1"}}